<?xml version="1.0" encoding="utf-8"?>
<!-- This URDF was automatically created by SolidWorks to URDF Exporter! Originally created by Stephen Brawner (brawner@gmail.com)
     Commit Version: 1.5.1-0-g916b5db  Build Version: 1.5.7152.31018
     For more information, please see http://wiki.ros.org/sw_urdf_exporter -->
<robot
  name="deliverbot_description">

  <!-- Init colour -->
  <material name="black">
    <color rgba="0.0 0.0 0.0 1.0"/>
  </material>

  <material name="orange">
    <color rgba="${255/255} ${108/255} ${10/255} 1.0"/>
  </material>

  <link
    name="base_link">
    <inertial>
      <origin
        xyz="-0.0054933 -4.1587E-05 0.062041"
        rpy="0 0 0" />
      <mass
        value="0.43668" />
      <inertia
        ixx="0.0029446"
        ixy="-1.0694E-05"
        ixz="8.6442E-05"
        iyy="0.0086395"
        iyz="-7.9718E-07"
        izz="0.0097467" />
    </inertial>
    <visual>
      <origin
        xyz="0 0 0"
        rpy="0 0 0" />
      <geometry>
        <mesh
          filename="package://deliverbot_description/meshes/LingFeng/LingFeng_base.STL" />
      </geometry>
      <material
        name="">
        <color
          rgba="1 0.812 0 1" />
      </material>
    </visual>
    <collision>
      <origin
        xyz="0 0 0"
        rpy="0 0 0" />
      <geometry>
        <mesh
          filename="package://deliverbot_description/meshes/LingFeng/LingFeng_base.STL" />
      </geometry>
    </collision>
  </link>
  <link name="base_footprint"/>

  <joint name="base_joint" type="fixed">
    <origin xyz="0 0 0" rpy="0 0 0"/>
    <parent link="base_footprint"/>
    <child link="base_link"/>
  </joint>

  <link
    name="wheel_la_link">
    <inertial>
      <origin
        xyz="-7.128E-08 -0.024133 -1.2354E-07"
        rpy="0 0 0" />
      <mass
        value="0.72164" />
      <inertia
        ixx="0.0014337"
        ixy="-1.4592E-09"
        ixz="1.906E-10"
        iyy="0.0026176"
        iyz="-2.5284E-09"
        izz="0.0014337" />
    </inertial>
    <visual>
      <origin
        xyz="0 0 0"
        rpy="0 0 0" />
      <geometry>
        <mesh
          filename="package://deliverbot_description/meshes/LingFeng/wheel_left.STL" />
      </geometry>
      <material
        name="">
        <color
          rgba="0.2 0.2 0.2 1" />
      </material>
    </visual>
    <collision>
      <origin
        xyz="0 0 0"
        rpy="0 0 0" />
      <geometry>
        <mesh
          filename="package://deliverbot_description/meshes/LingFeng/wheel_left.STL" />
      </geometry>
    </collision>
  </link>
  <joint
    name="wheel_la_joint"
    type="continuous">
    <origin
      xyz="0.12 0.1595 0.02"
      rpy="0 0 0" />
    <parent
      link="base_link" />
    <child
      link="wheel_la_link" />
    <axis
      xyz="0 1 0" rpy="0 0 0" />
  </joint>
  <link
    name="wheel_lb_link">
    <inertial>
      <origin
        xyz="-7.128E-08 -0.024133 -1.2354E-07"
        rpy="0 0 0" />
      <mass
        value="0.72164" />
      <inertia
        ixx="0.0014337"
        ixy="-1.4592E-09"
        ixz="1.906E-10"
        iyy="0.0026176"
        iyz="-2.5284E-09"
        izz="0.0014337" />
    </inertial>
    <visual>
      <origin
        xyz="0 0 0"
        rpy="0 0 0" />
      <geometry>
        <mesh
          filename="package://deliverbot_description/meshes/LingFeng/wheel_left.STL" />
      </geometry>
      <material
        name="">
        <color
          rgba="0.2 0.2 0.2 1" />
      </material>
    </visual>
    <collision>
      <origin
        xyz="0 0 0"
        rpy="0 0 0" />
      <geometry>
        <mesh
          filename="package://deliverbot_description/meshes/LingFeng/wheel_left.STL" />
      </geometry>
    </collision>
  </link>
  <joint
    name="wheel_lb_joint"
    type="continuous">
    <origin
      xyz="-0.12 0.1595 0.02"
      rpy="0 0 0" />
    <parent
      link="base_link" />
    <child
      link="wheel_lb_link" />
    <axis
      xyz="0 1 0" rpy="0 0 0" />
  </joint>
  <link
    name="wheel_ra_link">
    <inertial>
      <origin
        xyz="-7.1345E-08 0.024133 -1.235E-07"
        rpy="0 0 0" />
      <mass
        value="0.72164" />
      <inertia
        ixx="0.0014337"
        ixy="1.4601E-09"
        ixz="1.9073E-10"
        iyy="0.0026176"
        iyz="2.5279E-09"
        izz="0.0014337" />
    </inertial>
    <visual>
      <origin
        xyz="0 0 0"
        rpy="0 0 0" />
      <geometry>
        <mesh
          filename="package://deliverbot_description/meshes/LingFeng/wheel_right.STL" />
      </geometry>
      <material
        name="">
        <color
          rgba="0.2 0.2 0.2 1" />
      </material>
    </visual>
    <collision>
      <origin
        xyz="0 0 0"
        rpy="0 0 0" />
      <geometry>
        <mesh
          filename="package://deliverbot_description/meshes/LingFeng/wheel_right.STL" />
      </geometry>
    </collision>
  </link>
  <joint
    name="wheel_ra_joint"
    type="continuous">
    <origin
      xyz="0.12 -0.1595 0.02"
      rpy="0 0 0" />
    <parent
      link="base_link" />
    <child
      link="wheel_ra_link" />
    <axis
      xyz="0 1 0" rpy="0 0 0" />
  </joint>
  <link
    name="wheel_rb_link">
    <inertial>
      <origin
        xyz="-7.128E-08 -0.024133 -1.2354E-07"
        rpy="0 0 0" />
      <mass
        value="0.72164" />
      <inertia
      ixx="0.0014337"
      ixy="-1.4592E-09"
      ixz="1.906E-10"
      iyy="0.0026176"
      iyz="-2.5284E-09"
      izz="0.0014337" />
    </inertial>
    <visual>
      <origin
        xyz="0 0 0"
        rpy="0 0 0" />
      <geometry>
        <mesh
          filename="package://deliverbot_description/meshes/LingFeng/wheel_right.STL" />
      </geometry>
      <material
        name="">
        <color
          rgba="0.2 0.2 0.2 1" />
      </material>
    </visual>
    <collision>
      <origin
        xyz="0 0 0"
        rpy="0 0 0" />
      <geometry>
        <mesh
          filename="package://deliverbot_description/meshes/LingFeng/wheel_right.STL" />
      </geometry>
    </collision>
  </link>
  <joint
    name="wheel_rb_joint"
    type="continuous">
    <origin
      xyz="-0.12 -0.1595 0.02"
      rpy="0 0 0" />
    <parent
      link="base_link" />
    <child
      link="wheel_rb_link" />
    <axis
      xyz="0 1 0" rpy="0 0 0" />
  </joint>
  <gazebo reference="base_link">
    <material>Gazebo/Orange</material>
  </gazebo>
  <gazebo reference="wheel_la_link">
    <mu1 value="1.0"/>
    <mu2 value="1.0"/>
    <kp value="1000000.0"/>
    <kd value="1.0"/>
    <fdir1 value="1 0 0"/>
    <material>Gazebo/Black</material>
  </gazebo>
  <gazebo reference="wheel_lb_link">
    <mu1 value="1.0"/>
    <mu2 value="1.0"/>
    <kp value="1000000.0"/>
    <kd value="1.0"/>
    <fdir1 value="1 0 0"/>
    <material>Gazebo/Black</material>
  </gazebo>
  <gazebo reference="wheel_ra_link">
    <mu1 value="1.0"/>
    <mu2 value="1.0"/>
    <kp value="1000000.0"/>
    <kd value="1.0"/>
    <fdir1 value="1 0 0"/>
    <material>Gazebo/Black</material>
  </gazebo>
  <gazebo reference="wheel_rb_link">
    <mu1 value="1.0"/>
    <mu2 value="1.0"/>
    <kp value="1000000.0"/>
    <kd value="1.0"/>
    <fdir1 value="1 0 0"/>
    <material>Gazebo/Black</material>
  </gazebo>
  <gazebo>
    <plugin filename="libgazebo_ros_diff_drive.so" name="gazebo_base_controller">
      <odometry_frame>odom</odometry_frame>
      <publish_odom>true</publish_odom>
      <publish_odom_tf>true</publish_odom_tf>
      <robot_base_frame>base_footprint</robot_base_frame>
      <publish_wheel_tf>false</publish_wheel_tf>
      <update_rate>15.0</update_rate>
      <left_joint>wheel_la_joint</left_joint>
      <right_joint>wheel_lb_joint</right_joint>
      <wheel_separation>0.24</wheel_separation>
      <wheel_diameter>0.15</wheel_diameter>
      <max_wheel_acceleration>0.7</max_wheel_acceleration>
      <max_wheel_torque>8</max_wheel_torque>
      <ros>
        <argument>odom:=odom_raw</argument>
      </ros>
    </plugin>
  </gazebo>

  <gazebo>
    <plugin filename="libgazebo_ros_joint_state_publisher.so" name="gazebo_joint_publisher">
      <joint_name>wheel_la_joint</joint_name>
      <joint_name>wheel_lb_joint</joint_name>
      <joint_name>wheel_ra_joint</joint_name>
      <joint_name>wheel_rb_joint</joint_name>
      <update_rate>30.0</update_rate>
    </plugin>
  </gazebo>
  <ros2_control name="delierbot_system" type="system">
    <hardware>
      <xacro:if value="${use_fake_hardware}">
        <plugin>fake_components/GenericSystem</plugin>
        <param name="fake_sensor_commands">${fake_sensor_commands}</param>
        <param name="state_following_offset">0.0</param>
      </xacro:if>
      <xacro:unless value="${use_fake_hardware}">
        <plugin>ros2_control_demo_hardware/DiffBotSystemHardware</plugin>
        <param name="example_param_hw_start_duration_sec">2.0</param>
        <param name="example_param_hw_stop_duration_sec">3.0</param>
      </xacro:unless>
    </hardware>
    <joint name="wheel_la_joint">
      <command_interface name="velocity">
        <param name="min">-1</param>
        <param name="max">1</param>
      </command_interface>
      <state_interface name="position"/>
      <state_interface name="velocity"/>
    </joint>
    <joint name="wheel_lb_joint">
      <command_interface name="velocity">
        <param name="min">-1</param>
        <param name="max">1</param>
      </command_interface>
      <state_interface name="position"/>
      <state_interface name="velocity"/>
    </joint>
    <joint name="wheel_ra_joint">
      <command_interface name="velocity">
        <param name="min">-1</param>
        <param name="max">1</param>
      </command_interface>
      <state_interface name="position"/>
      <state_interface name="velocity"/>
    </joint>
    <joint name="wheel_rb_joint">
      <command_interface name="velocity">
        <param name="min">-1</param>
        <param name="max">1</param>
      </command_interface>
      <state_interface name="position"/>
      <state_interface name="velocity"/>
    </joint>
  </ros2_control>
</robot>
